[2025-07-24T14:20:43.865+0000] {local_task_job_runner.py:120} INFO - ::group::Pre task execution logs
[2025-07-24T14:20:43.926+0000] {taskinstance.py:2076} INFO - Dependencies all met for dep_context=non-requeueable deps ti=<TaskInstance: tunestream_etl.data_quality_check manual__2025-07-24T14:20:42.372337+00:00 [queued]>
[2025-07-24T14:20:43.942+0000] {taskinstance.py:2076} INFO - Dependencies all met for dep_context=requeueable deps ti=<TaskInstance: tunestream_etl.data_quality_check manual__2025-07-24T14:20:42.372337+00:00 [queued]>
[2025-07-24T14:20:43.943+0000] {taskinstance.py:2306} INFO - Starting attempt 1 of 4
[2025-07-24T14:20:43.975+0000] {taskinstance.py:2330} INFO - Executing <Task(PythonOperator): data_quality_check> on 2025-07-24 14:20:42.372337+00:00
[2025-07-24T14:20:43.999+0000] {logging_mixin.py:188} WARNING - /home/***/.local/lib/python3.12/site-packages/***/task/task_runner/standard_task_runner.py:62 DeprecationWarning: This process (pid=270) is multi-threaded, use of fork() may lead to deadlocks in the child.
[2025-07-24T14:20:44.002+0000] {standard_task_runner.py:64} INFO - Started process 271 to run task
[2025-07-24T14:20:43.992+0000] {standard_task_runner.py:90} INFO - Running: ['***', 'tasks', 'run', 'tunestream_etl', 'data_quality_check', 'manual__2025-07-24T14:20:42.372337+00:00', '--job-id', '39', '--raw', '--subdir', 'DAGS_FOLDER/tunestream_etl_dag.py', '--cfg-path', '/tmp/tmp82a80jou']
[2025-07-24T14:20:44.031+0000] {standard_task_runner.py:91} INFO - Job 39: Subtask data_quality_check
[2025-07-24T14:20:44.074+0000] {logging_mixin.py:188} WARNING - /home/***/.local/lib/python3.12/site-packages/***/settings.py:195 DeprecationWarning: The sql_alchemy_conn option in [core] has been moved to the sql_alchemy_conn option in [database] - the old setting has been used, but please update your config.
[2025-07-24T14:20:44.147+0000] {task_command.py:426} INFO - Running <TaskInstance: tunestream_etl.data_quality_check manual__2025-07-24T14:20:42.372337+00:00 [running]> on host da6b6b72382b
[2025-07-24T14:20:44.273+0000] {taskinstance.py:2648} INFO - Exporting env vars: AIRFLOW_CTX_DAG_OWNER='NamTH91' AIRFLOW_CTX_DAG_ID='tunestream_etl' AIRFLOW_CTX_TASK_ID='data_quality_check' AIRFLOW_CTX_EXECUTION_DATE='2025-07-24T14:20:42.372337+00:00' AIRFLOW_CTX_TRY_NUMBER='1' AIRFLOW_CTX_DAG_RUN_ID='manual__2025-07-24T14:20:42.372337+00:00'
[2025-07-24T14:20:44.281+0000] {taskinstance.py:430} INFO - ::endgroup::
[2025-07-24T14:20:52.336+0000] {taskinstance.py:441} INFO - ::group::Post task execution logs
[2025-07-24T14:20:52.337+0000] {taskinstance.py:2905} ERROR - Task failed with exception
Traceback (most recent call last):
  File "/home/airflow/.local/lib/python3.12/site-packages/airflow/models/taskinstance.py", line 465, in _execute_task
    result = _execute_callable(context=context, **execute_callable_kwargs)
             ^^^^^^^^^^^^^^^^^^^^^^^^^^^^^^^^^^^^^^^^^^^^^^^^^^^^^^^^^^^^^
  File "/home/airflow/.local/lib/python3.12/site-packages/airflow/models/taskinstance.py", line 432, in _execute_callable
    return execute_callable(context=context, **execute_callable_kwargs)
           ^^^^^^^^^^^^^^^^^^^^^^^^^^^^^^^^^^^^^^^^^^^^^^^^^^^^^^^^^^^^
  File "/home/airflow/.local/lib/python3.12/site-packages/airflow/models/baseoperator.py", line 401, in wrapper
    return func(self, *args, **kwargs)
           ^^^^^^^^^^^^^^^^^^^^^^^^^^^
  File "/home/airflow/.local/lib/python3.12/site-packages/airflow/operators/python.py", line 235, in execute
    return_value = self.execute_callable()
                   ^^^^^^^^^^^^^^^^^^^^^^^
  File "/home/airflow/.local/lib/python3.12/site-packages/airflow/operators/python.py", line 252, in execute_callable
    return self.python_callable(*self.op_args, **self.op_kwargs)
           ^^^^^^^^^^^^^^^^^^^^^^^^^^^^^^^^^^^^^^^^^^^^^^^^^^^^^
  File "/opt/airflow/dags/tunestream_etl_dag.py", line 211, in run_check_quality_data
    conn = psycopg2.connect(**conn_params)
           ^^^^^^^^^^^^^^^^^^^^^^^^^^^^^^^
  File "/home/airflow/.local/lib/python3.12/site-packages/psycopg2/__init__.py", line 122, in connect
    conn = _connect(dsn, connection_factory=connection_factory, **kwasync)
           ^^^^^^^^^^^^^^^^^^^^^^^^^^^^^^^^^^^^^^^^^^^^^^^^^^^^^^^^^^^^^^^
psycopg2.OperationalError: could not translate host name "hainam" to address: Temporary failure in name resolution

[2025-07-24T14:20:52.360+0000] {taskinstance.py:1206} INFO - Marking task as UP_FOR_RETRY. dag_id=tunestream_etl, task_id=data_quality_check, run_id=manual__2025-07-24T14:20:42.372337+00:00, execution_date=20250724T142042, start_date=20250724T142043, end_date=20250724T142052
[2025-07-24T14:20:52.388+0000] {standard_task_runner.py:110} ERROR - Failed to execute job 39 for task data_quality_check (could not translate host name "hainam" to address: Temporary failure in name resolution
; 271)
[2025-07-24T14:20:52.417+0000] {local_task_job_runner.py:243} INFO - Task exited with return code 1
[2025-07-24T14:20:52.437+0000] {taskinstance.py:3503} INFO - 0 downstream tasks scheduled from follow-on schedule check
[2025-07-24T14:20:52.442+0000] {local_task_job_runner.py:222} INFO - ::endgroup::
