[2025-07-24T17:17:55.750+0000] {local_task_job_runner.py:120} INFO - ::group::Pre task execution logs
[2025-07-24T17:17:55.772+0000] {taskinstance.py:2076} INFO - Dependencies all met for dep_context=non-requeueable deps ti=<TaskInstance: tunestream_etl.load_user_dim_table manual__2025-07-24T17:17:34.879728+00:00 [queued]>
[2025-07-24T17:17:55.782+0000] {taskinstance.py:2076} INFO - Dependencies all met for dep_context=requeueable deps ti=<TaskInstance: tunestream_etl.load_user_dim_table manual__2025-07-24T17:17:34.879728+00:00 [queued]>
[2025-07-24T17:17:55.782+0000] {taskinstance.py:2306} INFO - Starting attempt 1 of 4
[2025-07-24T17:17:55.796+0000] {taskinstance.py:2330} INFO - Executing <Task(PythonOperator): load_user_dim_table> on 2025-07-24 17:17:34.879728+00:00
[2025-07-24T17:17:55.805+0000] {standard_task_runner.py:90} INFO - Running: ['***', 'tasks', 'run', 'tunestream_etl', 'load_user_dim_table', 'manual__2025-07-24T17:17:34.879728+00:00', '--job-id', '119', '--raw', '--subdir', 'DAGS_FOLDER/tunestream_etl_dag.py', '--cfg-path', '/tmp/tmp29mejzoo']
[2025-07-24T17:17:55.809+0000] {standard_task_runner.py:91} INFO - Job 119: Subtask load_user_dim_table
[2025-07-24T17:17:55.810+0000] {logging_mixin.py:188} WARNING - /home/***/.local/lib/python3.12/site-packages/***/task/task_runner/standard_task_runner.py:62 DeprecationWarning: This process (pid=9658) is multi-threaded, use of fork() may lead to deadlocks in the child.
[2025-07-24T17:17:55.812+0000] {standard_task_runner.py:64} INFO - Started process 9660 to run task
[2025-07-24T17:17:55.838+0000] {logging_mixin.py:188} WARNING - /home/***/.local/lib/python3.12/site-packages/***/settings.py:195 DeprecationWarning: The sql_alchemy_conn option in [core] has been moved to the sql_alchemy_conn option in [database] - the old setting has been used, but please update your config.
[2025-07-24T17:17:55.889+0000] {task_command.py:426} INFO - Running <TaskInstance: tunestream_etl.load_user_dim_table manual__2025-07-24T17:17:34.879728+00:00 [running]> on host da6b6b72382b
[2025-07-24T17:17:56.017+0000] {taskinstance.py:2648} INFO - Exporting env vars: AIRFLOW_CTX_DAG_OWNER='NamTH91' AIRFLOW_CTX_DAG_ID='tunestream_etl' AIRFLOW_CTX_TASK_ID='load_user_dim_table' AIRFLOW_CTX_EXECUTION_DATE='2025-07-24T17:17:34.879728+00:00' AIRFLOW_CTX_TRY_NUMBER='1' AIRFLOW_CTX_DAG_RUN_ID='manual__2025-07-24T17:17:34.879728+00:00'
[2025-07-24T17:17:56.018+0000] {taskinstance.py:430} INFO - ::endgroup::
[2025-07-24T17:17:56.122+0000] {taskinstance.py:441} INFO - ::group::Post task execution logs
[2025-07-24T17:17:56.123+0000] {taskinstance.py:2905} ERROR - Task failed with exception
Traceback (most recent call last):
  File "/home/airflow/.local/lib/python3.12/site-packages/airflow/models/taskinstance.py", line 465, in _execute_task
    result = _execute_callable(context=context, **execute_callable_kwargs)
             ^^^^^^^^^^^^^^^^^^^^^^^^^^^^^^^^^^^^^^^^^^^^^^^^^^^^^^^^^^^^^
  File "/home/airflow/.local/lib/python3.12/site-packages/airflow/models/taskinstance.py", line 432, in _execute_callable
    return execute_callable(context=context, **execute_callable_kwargs)
           ^^^^^^^^^^^^^^^^^^^^^^^^^^^^^^^^^^^^^^^^^^^^^^^^^^^^^^^^^^^^
  File "/home/airflow/.local/lib/python3.12/site-packages/airflow/models/baseoperator.py", line 401, in wrapper
    return func(self, *args, **kwargs)
           ^^^^^^^^^^^^^^^^^^^^^^^^^^^
  File "/home/airflow/.local/lib/python3.12/site-packages/airflow/operators/python.py", line 235, in execute
    return_value = self.execute_callable()
                   ^^^^^^^^^^^^^^^^^^^^^^^
  File "/home/airflow/.local/lib/python3.12/site-packages/airflow/operators/python.py", line 252, in execute_callable
    return self.python_callable(*self.op_args, **self.op_kwargs)
           ^^^^^^^^^^^^^^^^^^^^^^^^^^^^^^^^^^^^^^^^^^^^^^^^^^^^^
  File "/opt/airflow/dags/tunestream_etl_dag.py", line 189, in _run
    cur.execute(query)
psycopg2.errors.CardinalityViolation: ON CONFLICT DO UPDATE command cannot affect row a second time
HINT:  Ensure that no rows proposed for insertion within the same command have duplicate constrained values.

[2025-07-24T17:17:56.157+0000] {taskinstance.py:1206} INFO - Marking task as UP_FOR_RETRY. dag_id=tunestream_etl, task_id=load_user_dim_table, run_id=manual__2025-07-24T17:17:34.879728+00:00, execution_date=20250724T171734, start_date=20250724T171755, end_date=20250724T171756
[2025-07-24T17:17:56.173+0000] {standard_task_runner.py:110} ERROR - Failed to execute job 119 for task load_user_dim_table (ON CONFLICT DO UPDATE command cannot affect row a second time
HINT:  Ensure that no rows proposed for insertion within the same command have duplicate constrained values.
; 9660)
[2025-07-24T17:17:56.188+0000] {local_task_job_runner.py:243} INFO - Task exited with return code 1
[2025-07-24T17:17:56.211+0000] {taskinstance.py:3503} INFO - 0 downstream tasks scheduled from follow-on schedule check
[2025-07-24T17:17:56.217+0000] {local_task_job_runner.py:222} INFO - ::endgroup::
