[2025-07-24T14:18:25.366+0000] {local_task_job_runner.py:120} INFO - ::group::Pre task execution logs
[2025-07-24T14:18:25.424+0000] {taskinstance.py:2076} INFO - Dependencies all met for dep_context=non-requeueable deps ti=<TaskInstance: tunestream_etl.data_quality_check manual__2025-07-22T10:16:36.248466+00:00 [queued]>
[2025-07-24T14:18:25.440+0000] {taskinstance.py:2076} INFO - Dependencies all met for dep_context=requeueable deps ti=<TaskInstance: tunestream_etl.data_quality_check manual__2025-07-22T10:16:36.248466+00:00 [queued]>
[2025-07-24T14:18:25.441+0000] {taskinstance.py:2306} INFO - Starting attempt 2 of 4
[2025-07-24T14:18:25.467+0000] {taskinstance.py:2330} INFO - Executing <Task(PythonOperator): data_quality_check> on 2025-07-22 10:16:36.248466+00:00
[2025-07-24T14:18:25.475+0000] {standard_task_runner.py:90} INFO - Running: ['***', 'tasks', 'run', 'tunestream_etl', 'data_quality_check', 'manual__2025-07-22T10:16:36.248466+00:00', '--job-id', '36', '--raw', '--subdir', 'DAGS_FOLDER/tunestream_etl_dag.py', '--cfg-path', '/tmp/tmpv4mtplry']
[2025-07-24T14:18:25.478+0000] {logging_mixin.py:188} WARNING - /home/***/.local/lib/python3.12/site-packages/***/task/task_runner/standard_task_runner.py:62 DeprecationWarning: This process (pid=171) is multi-threaded, use of fork() may lead to deadlocks in the child.
[2025-07-24T14:18:25.480+0000] {standard_task_runner.py:91} INFO - Job 36: Subtask data_quality_check
[2025-07-24T14:18:25.481+0000] {standard_task_runner.py:64} INFO - Started process 173 to run task
[2025-07-24T14:18:25.518+0000] {logging_mixin.py:188} WARNING - /home/***/.local/lib/python3.12/site-packages/***/settings.py:195 DeprecationWarning: The sql_alchemy_conn option in [core] has been moved to the sql_alchemy_conn option in [database] - the old setting has been used, but please update your config.
[2025-07-24T14:18:25.581+0000] {task_command.py:426} INFO - Running <TaskInstance: tunestream_etl.data_quality_check manual__2025-07-22T10:16:36.248466+00:00 [running]> on host da6b6b72382b
[2025-07-24T14:18:25.771+0000] {taskinstance.py:2648} INFO - Exporting env vars: AIRFLOW_CTX_DAG_OWNER='NamTH91' AIRFLOW_CTX_DAG_ID='tunestream_etl' AIRFLOW_CTX_TASK_ID='data_quality_check' AIRFLOW_CTX_EXECUTION_DATE='2025-07-22T10:16:36.248466+00:00' AIRFLOW_CTX_TRY_NUMBER='2' AIRFLOW_CTX_DAG_RUN_ID='manual__2025-07-22T10:16:36.248466+00:00'
[2025-07-24T14:18:25.772+0000] {taskinstance.py:430} INFO - ::endgroup::
[2025-07-24T14:18:33.992+0000] {taskinstance.py:441} INFO - ::group::Post task execution logs
[2025-07-24T14:18:33.993+0000] {taskinstance.py:2905} ERROR - Task failed with exception
Traceback (most recent call last):
  File "/home/airflow/.local/lib/python3.12/site-packages/airflow/models/taskinstance.py", line 465, in _execute_task
    result = _execute_callable(context=context, **execute_callable_kwargs)
             ^^^^^^^^^^^^^^^^^^^^^^^^^^^^^^^^^^^^^^^^^^^^^^^^^^^^^^^^^^^^^
  File "/home/airflow/.local/lib/python3.12/site-packages/airflow/models/taskinstance.py", line 432, in _execute_callable
    return execute_callable(context=context, **execute_callable_kwargs)
           ^^^^^^^^^^^^^^^^^^^^^^^^^^^^^^^^^^^^^^^^^^^^^^^^^^^^^^^^^^^^
  File "/home/airflow/.local/lib/python3.12/site-packages/airflow/models/baseoperator.py", line 401, in wrapper
    return func(self, *args, **kwargs)
           ^^^^^^^^^^^^^^^^^^^^^^^^^^^
  File "/home/airflow/.local/lib/python3.12/site-packages/airflow/operators/python.py", line 235, in execute
    return_value = self.execute_callable()
                   ^^^^^^^^^^^^^^^^^^^^^^^
  File "/home/airflow/.local/lib/python3.12/site-packages/airflow/operators/python.py", line 252, in execute_callable
    return self.python_callable(*self.op_args, **self.op_kwargs)
           ^^^^^^^^^^^^^^^^^^^^^^^^^^^^^^^^^^^^^^^^^^^^^^^^^^^^^
  File "/opt/airflow/dags/tunestream_etl_dag.py", line 211, in run_check_quality_data
    conn = psycopg2.connect(**conn_params)
           ^^^^^^^^^^^^^^^^^^^^^^^^^^^^^^^
  File "/home/airflow/.local/lib/python3.12/site-packages/psycopg2/__init__.py", line 122, in connect
    conn = _connect(dsn, connection_factory=connection_factory, **kwasync)
           ^^^^^^^^^^^^^^^^^^^^^^^^^^^^^^^^^^^^^^^^^^^^^^^^^^^^^^^^^^^^^^^
psycopg2.OperationalError: could not translate host name "hainam" to address: Temporary failure in name resolution

[2025-07-24T14:18:34.314+0000] {taskinstance.py:1206} INFO - Marking task as UP_FOR_RETRY. dag_id=tunestream_etl, task_id=data_quality_check, run_id=manual__2025-07-22T10:16:36.248466+00:00, execution_date=20250722T101636, start_date=20250724T141825, end_date=20250724T141834
[2025-07-24T14:18:34.348+0000] {standard_task_runner.py:110} ERROR - Failed to execute job 36 for task data_quality_check (could not translate host name "hainam" to address: Temporary failure in name resolution
; 173)
[2025-07-24T14:18:34.380+0000] {local_task_job_runner.py:243} INFO - Task exited with return code 1
[2025-07-24T14:18:34.405+0000] {taskinstance.py:3503} INFO - 0 downstream tasks scheduled from follow-on schedule check
[2025-07-24T14:18:34.413+0000] {local_task_job_runner.py:222} INFO - ::endgroup::
