[2025-07-22T10:27:03.193+0000] {local_task_job_runner.py:120} INFO - ::group::Pre task execution logs
[2025-07-22T10:27:05.236+0000] {taskinstance.py:2076} INFO - Dependencies all met for dep_context=non-requeueable deps ti=<TaskInstance: tunestream_etl.data_quality_check manual__2025-07-22T10:16:36.248466+00:00 [queued]>
[2025-07-22T10:27:05.777+0000] {taskinstance.py:2076} INFO - Dependencies all met for dep_context=requeueable deps ti=<TaskInstance: tunestream_etl.data_quality_check manual__2025-07-22T10:16:36.248466+00:00 [queued]>
[2025-07-22T10:27:05.800+0000] {taskinstance.py:2306} INFO - Starting attempt 1 of 4
[2025-07-22T10:27:06.318+0000] {taskinstance.py:2330} INFO - Executing <Task(PythonOperator): data_quality_check> on 2025-07-22 10:16:36.248466+00:00
[2025-07-22T10:27:06.764+0000] {logging_mixin.py:188} WARNING - /home/***/.local/lib/python3.12/site-packages/***/task/task_runner/standard_task_runner.py:62 DeprecationWarning: This process (pid=1735) is multi-threaded, use of fork() may lead to deadlocks in the child.
[2025-07-22T10:27:06.813+0000] {standard_task_runner.py:64} INFO - Started process 1749 to run task
[2025-07-22T10:27:06.613+0000] {standard_task_runner.py:90} INFO - Running: ['***', 'tasks', 'run', 'tunestream_etl', 'data_quality_check', 'manual__2025-07-22T10:16:36.248466+00:00', '--job-id', '28', '--raw', '--subdir', 'DAGS_FOLDER/tunestream_etl_dag.py', '--cfg-path', '/tmp/tmph4qn9i1y']
[2025-07-22T10:27:06.882+0000] {standard_task_runner.py:91} INFO - Job 28: Subtask data_quality_check
[2025-07-22T10:27:08.471+0000] {logging_mixin.py:188} WARNING - /home/***/.local/lib/python3.12/site-packages/***/settings.py:195 DeprecationWarning: The sql_alchemy_conn option in [core] has been moved to the sql_alchemy_conn option in [database] - the old setting has been used, but please update your config.
[2025-07-22T10:27:11.337+0000] {task_command.py:426} INFO - Running <TaskInstance: tunestream_etl.data_quality_check manual__2025-07-22T10:16:36.248466+00:00 [running]> on host 2ad5d09a42d7
[2025-07-22T10:27:16.967+0000] {taskinstance.py:2648} INFO - Exporting env vars: AIRFLOW_CTX_DAG_OWNER='NamTH91' AIRFLOW_CTX_DAG_ID='tunestream_etl' AIRFLOW_CTX_TASK_ID='data_quality_check' AIRFLOW_CTX_EXECUTION_DATE='2025-07-22T10:16:36.248466+00:00' AIRFLOW_CTX_TRY_NUMBER='1' AIRFLOW_CTX_DAG_RUN_ID='manual__2025-07-22T10:16:36.248466+00:00'
[2025-07-22T10:27:17.101+0000] {taskinstance.py:430} INFO - ::endgroup::
[2025-07-22T10:27:21.677+0000] {taskinstance.py:441} INFO - ::group::Post task execution logs
[2025-07-22T10:27:21.683+0000] {taskinstance.py:2905} ERROR - Task failed with exception
Traceback (most recent call last):
  File "/home/airflow/.local/lib/python3.12/site-packages/airflow/models/taskinstance.py", line 465, in _execute_task
    result = _execute_callable(context=context, **execute_callable_kwargs)
             ^^^^^^^^^^^^^^^^^^^^^^^^^^^^^^^^^^^^^^^^^^^^^^^^^^^^^^^^^^^^^
  File "/home/airflow/.local/lib/python3.12/site-packages/airflow/models/taskinstance.py", line 432, in _execute_callable
    return execute_callable(context=context, **execute_callable_kwargs)
           ^^^^^^^^^^^^^^^^^^^^^^^^^^^^^^^^^^^^^^^^^^^^^^^^^^^^^^^^^^^^
  File "/home/airflow/.local/lib/python3.12/site-packages/airflow/models/baseoperator.py", line 401, in wrapper
    return func(self, *args, **kwargs)
           ^^^^^^^^^^^^^^^^^^^^^^^^^^^
  File "/home/airflow/.local/lib/python3.12/site-packages/airflow/operators/python.py", line 235, in execute
    return_value = self.execute_callable()
                   ^^^^^^^^^^^^^^^^^^^^^^^
  File "/home/airflow/.local/lib/python3.12/site-packages/airflow/operators/python.py", line 252, in execute_callable
    return self.python_callable(*self.op_args, **self.op_kwargs)
           ^^^^^^^^^^^^^^^^^^^^^^^^^^^^^^^^^^^^^^^^^^^^^^^^^^^^^
  File "/opt/airflow/dags/tunestream_etl_dag.py", line 211, in run_check_quality_data
    conn = psycopg2.connect(**conn_params)
           ^^^^^^^^^^^^^^^^^^^^^^^^^^^^^^^
  File "/home/airflow/.local/lib/python3.12/site-packages/psycopg2/__init__.py", line 122, in connect
    conn = _connect(dsn, connection_factory=connection_factory, **kwasync)
           ^^^^^^^^^^^^^^^^^^^^^^^^^^^^^^^^^^^^^^^^^^^^^^^^^^^^^^^^^^^^^^^
psycopg2.OperationalError: could not translate host name "hainam" to address: Name or service not known

[2025-07-22T10:27:21.781+0000] {taskinstance.py:1206} INFO - Marking task as UP_FOR_RETRY. dag_id=tunestream_etl, task_id=data_quality_check, run_id=manual__2025-07-22T10:16:36.248466+00:00, execution_date=20250722T101636, start_date=20250722T102705, end_date=20250722T102721
[2025-07-22T10:27:21.831+0000] {standard_task_runner.py:110} ERROR - Failed to execute job 28 for task data_quality_check (could not translate host name "hainam" to address: Name or service not known
; 1749)
[2025-07-22T10:27:21.912+0000] {local_task_job_runner.py:243} INFO - Task exited with return code 1
[2025-07-22T10:27:21.975+0000] {local_task_job_runner.py:222} INFO - ::endgroup::
